{
 "cells": [
  {
   "cell_type": "code",
   "execution_count": 12,
   "metadata": {
    "collapsed": true
   },
   "outputs": [],
   "source": [
    "# import Entry model and sd object\n",
    "from models import *"
   ]
  },
  {
   "cell_type": "code",
   "execution_count": 13,
   "metadata": {},
   "outputs": [
    {
     "data": {
      "text/plain": [
       "<SQLAlchemy engine=sqlite:////home/mohamed/Desktop/blog/app/blog.db>"
      ]
     },
     "execution_count": 13,
     "metadata": {},
     "output_type": "execute_result"
    }
   ],
   "source": [
    "# What is db?\n",
    "db"
   ]
  },
  {
   "cell_type": "code",
   "execution_count": 14,
   "metadata": {
    "collapsed": true
   },
   "outputs": [],
   "source": [
    "# What is Entry and how do we create it?\n",
    "Entry?"
   ]
  },
  {
   "cell_type": "code",
   "execution_count": 15,
   "metadata": {},
   "outputs": [
    {
     "data": {
      "text/plain": [
       "True"
      ]
     },
     "execution_count": 15,
     "metadata": {},
     "output_type": "execute_result"
    }
   ],
   "source": [
    "#We can create Entry objects by passing column values in as the keyword-arguments, in the following steps:\n",
    "\n",
    "# 1- write the entry\n",
    "first_entry = Entry(title='First entry', body='This is the body of my first entry.')\n",
    "# 2- add it to the database session (session is an object that represents our actions on the database)\n",
    "db.session.add(first_entry)\n",
    "     ### until now we didn't save entry to our database, to confirm that try to get entry unique id, you will get none as answer, because we didn't do commit to databse yet.\n",
    "first_entry.id is None"
   ]
  },
  {
   "cell_type": "code",
   "execution_count": 16,
   "metadata": {},
   "outputs": [
    {
     "ename": "InvalidRequestError",
     "evalue": "This Session's transaction has been rolled back due to a previous exception during flush. To begin a new transaction with this Session, first issue Session.rollback(). Original exception was: (sqlite3.OperationalError) no such table: entry [SQL: u'INSERT INTO entry (title, slug, body, created_timestamp, modified_timestamp) VALUES (?, ?, ?, ?, ?)'] [parameters: ('First entry', None, 'This is the body of my first entry.', '2017-11-01 16:45:45.603293', '2017-11-01 16:45:45.603415')]",
     "output_type": "error",
     "traceback": [
      "\u001b[0;31m---------------------------------------------------------------------------\u001b[0m",
      "\u001b[0;31mInvalidRequestError\u001b[0m                       Traceback (most recent call last)",
      "\u001b[0;32m<ipython-input-16-a9109c7a8d35>\u001b[0m in \u001b[0;36m<module>\u001b[0;34m()\u001b[0m\n\u001b[1;32m      1\u001b[0m \u001b[0;31m# 3- Now commit the new entry, and check ID again\u001b[0m\u001b[0;34m\u001b[0m\u001b[0;34m\u001b[0m\u001b[0m\n\u001b[0;32m----> 2\u001b[0;31m \u001b[0mdb\u001b[0m\u001b[0;34m.\u001b[0m\u001b[0msession\u001b[0m\u001b[0;34m.\u001b[0m\u001b[0mcommit\u001b[0m\u001b[0;34m(\u001b[0m\u001b[0;34m)\u001b[0m\u001b[0;34m\u001b[0m\u001b[0m\n\u001b[0m\u001b[1;32m      3\u001b[0m \u001b[0mfirst_entry\u001b[0m\u001b[0;34m.\u001b[0m\u001b[0mid\u001b[0m\u001b[0;34m\u001b[0m\u001b[0m\n",
      "\u001b[0;32m/home/mohamed/anaconda3/lib/python2.7/site-packages/sqlalchemy/orm/scoping.pyc\u001b[0m in \u001b[0;36mdo\u001b[0;34m(self, *args, **kwargs)\u001b[0m\n\u001b[1;32m    155\u001b[0m \u001b[0;32mdef\u001b[0m \u001b[0minstrument\u001b[0m\u001b[0;34m(\u001b[0m\u001b[0mname\u001b[0m\u001b[0;34m)\u001b[0m\u001b[0;34m:\u001b[0m\u001b[0;34m\u001b[0m\u001b[0m\n\u001b[1;32m    156\u001b[0m     \u001b[0;32mdef\u001b[0m \u001b[0mdo\u001b[0m\u001b[0;34m(\u001b[0m\u001b[0mself\u001b[0m\u001b[0;34m,\u001b[0m \u001b[0;34m*\u001b[0m\u001b[0margs\u001b[0m\u001b[0;34m,\u001b[0m \u001b[0;34m**\u001b[0m\u001b[0mkwargs\u001b[0m\u001b[0;34m)\u001b[0m\u001b[0;34m:\u001b[0m\u001b[0;34m\u001b[0m\u001b[0m\n\u001b[0;32m--> 157\u001b[0;31m         \u001b[0;32mreturn\u001b[0m \u001b[0mgetattr\u001b[0m\u001b[0;34m(\u001b[0m\u001b[0mself\u001b[0m\u001b[0;34m.\u001b[0m\u001b[0mregistry\u001b[0m\u001b[0;34m(\u001b[0m\u001b[0;34m)\u001b[0m\u001b[0;34m,\u001b[0m \u001b[0mname\u001b[0m\u001b[0;34m)\u001b[0m\u001b[0;34m(\u001b[0m\u001b[0;34m*\u001b[0m\u001b[0margs\u001b[0m\u001b[0;34m,\u001b[0m \u001b[0;34m**\u001b[0m\u001b[0mkwargs\u001b[0m\u001b[0;34m)\u001b[0m\u001b[0;34m\u001b[0m\u001b[0m\n\u001b[0m\u001b[1;32m    158\u001b[0m     \u001b[0;32mreturn\u001b[0m \u001b[0mdo\u001b[0m\u001b[0;34m\u001b[0m\u001b[0m\n\u001b[1;32m    159\u001b[0m \u001b[0;34m\u001b[0m\u001b[0m\n",
      "\u001b[0;32m/home/mohamed/anaconda3/lib/python2.7/site-packages/sqlalchemy/orm/session.pyc\u001b[0m in \u001b[0;36mcommit\u001b[0;34m(self)\u001b[0m\n\u001b[1;32m    904\u001b[0m                 \u001b[0;32mraise\u001b[0m \u001b[0msa_exc\u001b[0m\u001b[0;34m.\u001b[0m\u001b[0mInvalidRequestError\u001b[0m\u001b[0;34m(\u001b[0m\u001b[0;34m\"No transaction is begun.\"\u001b[0m\u001b[0;34m)\u001b[0m\u001b[0;34m\u001b[0m\u001b[0m\n\u001b[1;32m    905\u001b[0m \u001b[0;34m\u001b[0m\u001b[0m\n\u001b[0;32m--> 906\u001b[0;31m         \u001b[0mself\u001b[0m\u001b[0;34m.\u001b[0m\u001b[0mtransaction\u001b[0m\u001b[0;34m.\u001b[0m\u001b[0mcommit\u001b[0m\u001b[0;34m(\u001b[0m\u001b[0;34m)\u001b[0m\u001b[0;34m\u001b[0m\u001b[0m\n\u001b[0m\u001b[1;32m    907\u001b[0m \u001b[0;34m\u001b[0m\u001b[0m\n\u001b[1;32m    908\u001b[0m     \u001b[0;32mdef\u001b[0m \u001b[0mprepare\u001b[0m\u001b[0;34m(\u001b[0m\u001b[0mself\u001b[0m\u001b[0;34m)\u001b[0m\u001b[0;34m:\u001b[0m\u001b[0;34m\u001b[0m\u001b[0m\n",
      "\u001b[0;32m/home/mohamed/anaconda3/lib/python2.7/site-packages/sqlalchemy/orm/session.pyc\u001b[0m in \u001b[0;36mcommit\u001b[0;34m(self)\u001b[0m\n\u001b[1;32m    457\u001b[0m \u001b[0;34m\u001b[0m\u001b[0m\n\u001b[1;32m    458\u001b[0m     \u001b[0;32mdef\u001b[0m \u001b[0mcommit\u001b[0m\u001b[0;34m(\u001b[0m\u001b[0mself\u001b[0m\u001b[0;34m)\u001b[0m\u001b[0;34m:\u001b[0m\u001b[0;34m\u001b[0m\u001b[0m\n\u001b[0;32m--> 459\u001b[0;31m         \u001b[0mself\u001b[0m\u001b[0;34m.\u001b[0m\u001b[0m_assert_active\u001b[0m\u001b[0;34m(\u001b[0m\u001b[0mprepared_ok\u001b[0m\u001b[0;34m=\u001b[0m\u001b[0mTrue\u001b[0m\u001b[0;34m)\u001b[0m\u001b[0;34m\u001b[0m\u001b[0m\n\u001b[0m\u001b[1;32m    460\u001b[0m         \u001b[0;32mif\u001b[0m \u001b[0mself\u001b[0m\u001b[0;34m.\u001b[0m\u001b[0m_state\u001b[0m \u001b[0;32mis\u001b[0m \u001b[0;32mnot\u001b[0m \u001b[0mPREPARED\u001b[0m\u001b[0;34m:\u001b[0m\u001b[0;34m\u001b[0m\u001b[0m\n\u001b[1;32m    461\u001b[0m             \u001b[0mself\u001b[0m\u001b[0;34m.\u001b[0m\u001b[0m_prepare_impl\u001b[0m\u001b[0;34m(\u001b[0m\u001b[0;34m)\u001b[0m\u001b[0;34m\u001b[0m\u001b[0m\n",
      "\u001b[0;32m/home/mohamed/anaconda3/lib/python2.7/site-packages/sqlalchemy/orm/session.pyc\u001b[0m in \u001b[0;36m_assert_active\u001b[0;34m(self, prepared_ok, rollback_ok, deactive_ok, closed_msg)\u001b[0m\n\u001b[1;32m    274\u001b[0m                         \u001b[0;34m\"first issue Session.rollback().\"\u001b[0m\u001b[0;34m\u001b[0m\u001b[0m\n\u001b[1;32m    275\u001b[0m                         \u001b[0;34m\" Original exception was: %s\"\u001b[0m\u001b[0;34m\u001b[0m\u001b[0m\n\u001b[0;32m--> 276\u001b[0;31m                         \u001b[0;34m%\u001b[0m \u001b[0mself\u001b[0m\u001b[0;34m.\u001b[0m\u001b[0m_rollback_exception\u001b[0m\u001b[0;34m\u001b[0m\u001b[0m\n\u001b[0m\u001b[1;32m    277\u001b[0m                     )\n\u001b[1;32m    278\u001b[0m                 \u001b[0;32melif\u001b[0m \u001b[0;32mnot\u001b[0m \u001b[0mdeactive_ok\u001b[0m\u001b[0;34m:\u001b[0m\u001b[0;34m\u001b[0m\u001b[0m\n",
      "\u001b[0;31mInvalidRequestError\u001b[0m: This Session's transaction has been rolled back due to a previous exception during flush. To begin a new transaction with this Session, first issue Session.rollback(). Original exception was: (sqlite3.OperationalError) no such table: entry [SQL: u'INSERT INTO entry (title, slug, body, created_timestamp, modified_timestamp) VALUES (?, ?, ?, ?, ?)'] [parameters: ('First entry', None, 'This is the body of my first entry.', '2017-11-01 16:45:45.603293', '2017-11-01 16:45:45.603415')]"
     ]
    }
   ],
   "source": [
    "# 3- Now commit the new entry, and check ID again\n",
    "db.session.commit()\n",
    "first_entry.id"
   ]
  }
 ],
 "metadata": {
  "kernelspec": {
   "display_name": "Python 2",
   "language": "python",
   "name": "python2"
  },
  "language_info": {
   "codemirror_mode": {
    "name": "ipython",
    "version": 2
   },
   "file_extension": ".py",
   "mimetype": "text/x-python",
   "name": "python",
   "nbconvert_exporter": "python",
   "pygments_lexer": "ipython2",
   "version": "2.7.13"
  }
 },
 "nbformat": 4,
 "nbformat_minor": 2
}
